{
  "comments": [
    {
      "key": {
        "uuid": "39b40fb9_e3d11a26",
        "filename": "sw/CustomTarget_generated.mk",
        "patchSetId": 5
      },
      "lineNbr": 16,
      "author": {
        "id": 1000022
      },
      "writtenOn": "2020-02-25T10:01:37Z",
      "side": 1,
      "message": "here a dependency is missing on \"$(call gb_ExternalExecutable_get_dependencies,python)\" - this only matters for the --enable-python\u003dfully-internal case iirc... please add it in a follow-up patch",
      "revId": "e6b9bc3f2ecf0fb7fde5b02f9d750ccbe022f4c1",
      "serverId": "6622c302-437a-49ad-a91d-55ba7dcf1615",
      "unresolved": true
    },
    {
      "key": {
        "uuid": "5779b536_ea226dab",
        "filename": "sw/CustomTarget_generated.mk",
        "patchSetId": 5
      },
      "lineNbr": 20,
      "author": {
        "id": 1000022
      },
      "writtenOn": "2020-02-25T10:01:37Z",
      "side": 1,
      "message": "same here",
      "revId": "e6b9bc3f2ecf0fb7fde5b02f9d750ccbe022f4c1",
      "serverId": "6622c302-437a-49ad-a91d-55ba7dcf1615",
      "unresolved": true
    }
  ]
}